Workbook

Sheet Reena
A1: CLIENT | B1: INVOICE NO. | C1: INVOICE DATE | D1: CLIENT TRN | E1: DESCRIPTION | F1: INVOICE SUB-TOTAL | G1: REBATE | H1: INVOICE SUB-TOTAL AFTER REBATE | I1: VAT % AMOUNT | J1: TOTAL INVOICE AMOUNT | K1: Sales Person | L1: =COUNTA(B:B)-1 -> 189 | M1: =GETPIVOTDATA("Count of INVOICE NO.",#REF!)+GETPIVOTDATA("Count of INVOICE NO.",#REF!) -> #REF! | N1: =SUM(F:F) -> 542386.71
A2: Stellar Advertising LLC | B2: 24-0001 | C2: 45293 | D2: 100542487200003 | E2: A3 Poster - Jebel Ali School | F2: 425.49 | H2: =F2-G2 -> 425.49 | I2: =F2*5% -> 21.2745 | J2: =F2+I2 -> 446.7645 | K2: REENA
A3: Stellar Advertising LLC | B3: 24-0002 | C3: 45295 | D3: 100542487200003 | E3: A5 Booklet - DBSJP (Nov/Dec) | F3: 415 | H3: =F3-G3 -> 415 | I3: =F3*5% -> 20.75 | J3: =F3+I3 -> 435.75 | K3: REENA
A4: Aurantius Real Estate Broker | B4: 24-0003 | C4: 45295 | D4: 104166051300003 | E4: Business Cards ( Ferhat Doghan ) | F4: 475 | H4: =F4-G4 -> 475 | I4: =F4*5% -> 23.75 | J4: =F4+I4 -> 498.75 | K4: REENA
A5: A-Technologies FZCO | B5: 24-0004 | C5: 45306 | D5: 100312976200003 | E5: Water Bottle , A5 Notebook (Anti-Microbial) , Metal Pen , Box | F5: 5850 | H5: =F5-G5 -> 5850 | I5: =F5*5% -> 292.5 | J5: =F5+I5 -> 6142.5 | K5: MARINELLE
A6: EMIRATES FOR UNIVERSAL TYRES L.L.C. | B6: 24-0005 | C6: 45297 | D6: 100032677500003 | E6: Sticker (Paper) | F6: 425 | H6: =F6-G6 -> 425 | I6: =F6*5% -> 21.25 | J6: =F6+I6 -> 446.25 | K6: REENA
A7: GRAND STAR ALUMINUM & GLASS L.L.C | B7: 24-0006 | C7: 45296 | D7: 100522321700003 | E7: Wooden Board | F7: 7600 | H7: =F7-G7 -> 7600 | I7: =F7*5% -> 380 | J7: =F7+I7 -> 7980 | K7: REENA
A8: VISIONARY FURNITURE TRADING L.L.C | B8: 24-0007 | C8: 45302 | D8: 104037069200003 | E8: Business Cards , Polo Shirts | F8: 848 | H8: =F8-G8 -> 848 | I8: =F8*5% -> 42.4 | J8: =F8+I8 -> 890.4 | K8: REENA
A9: Navitas Middle East FZ - LLC | B9: 24-0008 | C9: 45300 | D9: 100430750800003 | E9: Round neck Tshirt | F9: 380 | H9: =F9-G9 -> 380 | I9: =F9*5% -> 19 | J9: =F9+I9 -> 399 | K9: REENA
A10: Trane BVBA (Abu Dhabi) | B10: 24-0009 | C10: 45316 | D10: 100348311000003 | E10: Business Card ( Mohamed Ben Hamouda ) | F10: 405 | H10: =F10-G10 -> 405 | I10: =F10*5% -> 20.25 | J10: =F10+I10 -> 425.25 | K10: REENA
A11: M Y WORLD TRADING L.L.C | B11: 24-0010 | C11: 45300 | D11: 104014963300003 | E11: Business Cards ( Mr. Mehdi M Taki , Mr. Muhammed Midlaj ) | F11: 530 | H11: =F11-G11 -> 530 | I11: =F11*5% -> 26.5 | J11: =F11+I11 -> 556.5 | K11: REENA
A12: GRAND STAR ALUMINUM & GLASS L.L.C | B12: 24-0011 | C12: 45302 | D12: 100522321700003 | E12: Acrylic Stand | F12: 760 | H12: =F12-G12 -> 760 | I12: =F12*5% -> 38 | J12: =F12+I12 -> 798 | K12: REENA
A13: IDP Education Services Nigeria Limited | B13: 24-0012 | C13: 45300 | D13: - | E13: Polo Shirt | F13: =3.67*62.1 -> 227.907 | H13: =F13-G13 -> 227.907 | I13: =F13*5% -> 11.39535 | J13: =F13+I13 -> 239.30235 | K13: REENA
A14: M E A D Medical Supplies & Equipment L.L.C | B14: 24-0013 | C14: 45303 | D14: 100540543400003 | E14: NCR Book | F14: 475 | H14: =F14-G14 -> 475 | I14: =F14*5% -> 23.75 | J14: =F14+I14 -> 498.75 | K14: MARINELLE
A15: Stellar Advertising LLC | B15: 24-0014 | C15: 45303 | D15: 100542487200003 | E15: Poster , Flag ( Raha International School ) | F15: 440 | H15: =F15-G15 -> 440 | I15: =F15*5% -> 22 | J15: =F15+I15 -> 462 | K15: REENA
A16: Lloyds Energy DMCC | B16: 24-0015 | C16: 45303 | D16: 100056728700003 | E16: Signage (Without Light) | F16: 1250 | H16: =F16-G16 -> 1250 | I16: =F16*5% -> 62.5 | J16: =F16+I16 -> 1312.5 | K16: MARINELLE
A17: EMIRATES FOR UNIVERSAL TYRES L.L.C. | B17: 24-0016 | C17: 45303 | D17: 100032677500003 | E17: Business card ( Rineesh Ali ) | F17: 165 | H17: =F17-G17 -> 165 | I17: =F17*5% -> 8.25 | J17: =F17+I17 -> 173.25 | K17: REENA
A18: Bianca and Bianco Trading LLC | B18: 24-0017 | C18: 45304 | D18: 100482284500003 | E18: Business Card | F18: 825 | H18: =F18-G18 -> 825 | I18: =F18*5% -> 41.25 | J18: =F18+I18 -> 866.25 | K18: REENA
A19: Logic Utilities District Cooling Services LLC | B19: 24-0018 | C19: 45316 | D19: 100567483100003 | E19: Polo Shirts | F19: 4252.5 | H19: =F19-G19 -> 4252.5 | I19: =F19*5% -> 212.625 | J19: =F19+I19 -> 4465.125 | K19: MARINELLE
A20: FAD Institute of Luxury Fashion and Style Dubai | B20: 24-0019 | C20: 45307 | D20: - | E20: Certificate Holder | F20: 1690 | H20: =F20-G20 -> 1690 | I20: =F20*5% -> 84.5 | J20: =F20+I20 -> 1774.5 | K20: MARINELLE
A21: Ingersoll-Rand Technical and Services S A R L (Dubai Branch) | B21: 24-0020 | C21: 45306 | D21: 100399495900003 | E21: Business Card | F21: 310 | H21: =F21-G21 -> 310 | I21: =F21*5% -> 15.5 | J21: =F21+I21 -> 325.5 | K21: MARINELLE
A22: JUBAILI BROS S.A.L. | B22: 24-0021 | C22: 45307 | D22: 100293287700003 | E22: Car Sunshades (Tyvek) | F22: 5975 | H22: =F22-G22 -> 5975 | I22: =F22*5% -> 298.75 | J22: =F22+I22 -> 6273.75 | K22: MARINELLE
A23: Global Connect | B23: 24-0022 | C23: 45303 | D23: - | E23: Rubber stamp | F23: 120 | H23: =F23-G23 -> 120 | I23: =F23*5% -> 6 | J23: =F23+I23 -> 126 | K23: REENA
A24: A-Technologies FZCO | B24: 24-0024 | C24: 45307 | D24: 100312976200003 | E24: Prints for Gift Box | F24: 200 | H24: =F24-G24 -> 200 | I24: =F24*5% -> 10 | J24: =F24+I24 -> 210 | K24: MARINELLE
A25: Radiometer Medical ApS | B25: 24-0025 | C25: 45313 | D25: - | E25: Pop Up Banner (Straight) , Roll up , Book Mark (Steel) , Table Flag with Stand | F25: 7595.24 | H25: =F25-G25 -> 7595.24 | I25: =F25*5% -> 379.762 | J25: =F25+I25 -> 7975.002 | K25: MARINELLE
... A92: Trane BVBA (Dubai Branch) | B92: 24-0093 | C92: 45335 | D92: 100235699400003 | E92: Crystal Trophy | F92: 1800 | H92: =F92-G92 -> 1800 | I92: =F92*5% -> 90 | J92: =F92+I92 -> 1890 | K92: REENA
A93: Krishna International FZCO | B93: 24-0094 | C93: 45332 | D93: 100060213400003 | E93: Wedding Luggage Tags | F93: 13000 | H93: =F93-G93 -> 13000 | I93: =F93*5% -> 650 | J93: =F93+I93 -> 13650 | K93: REENA
A94: One Blue Clover FZCO | B94: 24-0095 | C94: 45338 | D94: - | E94: Letterhead | F94: 525 | H94: =F94-G94 -> 525 | I94: =F94*5% -> 26.25 | J94: =F94+I94 -> 551.25 | K94: REENA
A95: Stellar Advertising LLC | B95: 24-0096 | C95: 45337 | D95: 100542487200003 | E95: Selfie Frame - DBSJP , Prop - #Outstanding | F95: 595 | H95: =F95-G95 -> 595 | I95: =F95*5% -> 29.75 | J95: =F95+I95 -> 624.75 | K95: REENA
A96: Stellar Advertising LLC | B96: 24-0097 | C96: 45338 | D96: 100542487200003 | E96: Roll Up - AAG | F96: 145 | H96: =F96-G96 -> 145 | I96: =F96*5% -> 7.25 | J96: =F96+I96 -> 152.25 | K96: REENA
A97: M E A D Medical Supplies & Equipment L.L.C | B97: 24-0098 | C97: 45341 | D97: 100540543400003 | E97: NCR Book , Business Cards | F97: 860 | H97: =F97-G97 -> 860 | I97: =F97*5% -> 43 | J97: =F97+I97 -> 903 | K97: MARINELLE
A98: Stellar Advertising LLC | B98: 24-0099 | C98: 45342 | D98: 100542487200003 | E98: Letterhead - FICHTE | F98: 625 | H98: =F98-G98 -> 625 | I98: =F98*5% -> 31.25 | J98: =F98+I98 -> 656.25 | K98: REENA
A99: Golden Tower Technologies | B99: 24-0100 | C99: 45338 | D99: 100470289800003 | E99: Flex to be changed for existing light box | F99: 8850 | H99: =F99-G99 -> 8850 | I99: =F99*5% -> 442.5 | J99: =F99+I99 -> 9292.5 | K99: PROFORMA
A100: Thermo Fisher Scientific S.P.A. | B100: 24-0101 | C100: 45338 | D100: IT 07817950152 | E100: Flyer , Recycled 6-in-1 Charging Cable | F100: 3335 | H100: =F100-G100 -> 3335 | I100: =F100*5% -> 166.75 | J100: =F100+I100 -> 3501.75 | K100: MARINELLE
A101: Griffith College | B101: 24-0102 | C101: 45338 | D101: - | E101: Brochure | F101: 1225 | H101: =F101-G101 -> 1225 | I101: =F101*5% -> 61.25 | J101: =F101+I101 -> 1286.25 | K101: REENA
A102: IDP EDUCATION L.L.C | B102: 24-0103 | C102: 45341 | D102: 100593105800003 | E102: Dubai Roadshow Millenium Downtown, 17th Feb 2024 | F102: 103245.5 | H102: =F102-G102 -> 103245.5 | I102: =F102*5% -> 5162.275 | J102: =F102+I102 -> 108407.77 | K102: REENA
A103: IDP EDUCATION L.L.C | B103: 24-0104 | C103: 45341 | D103: 100593105800003 | E103: Abu Dhabi Roadshow 18 Feb 2024, InterContinental | F103: 51717.75 | H103: =F103-G103 -> 51717.75 | I103: =F103*5% -> 2585.8875 | J103: =F103+I103 -> 54303.637 | K103: REENA
A104: DYNAMIC EMPLOYMENT SERVICES L.L.C | B104: 24-0105 | C104: 45343 | D104: 100323347300003 | E104: Parking Signage | F104: 892.5 | H104: =F104-G104 -> 892.5 | I104: =F104*5% -> 44.625 | J104: =F104+I104 -> 937.125 | K104: MARINELLE
A105: Stellar Advertising LLC | B105: 24-0106 | C105: 45343 | D105: 100542487200003 | E105: Flyer - Taylor Wessing | F105: 190 | H105: =F105-G105 -> 190 | I105: =F105*5% -> 9.5 | J105: =F105+I105 -> 199.5 | K105: REENA
A106: Stellar Advertising LLC | B106: 24-0107 | C106: 45342 | D106: 100542487200003 | E106: Journal - DBSEH | F106: 585 | H106: =F106-G106 -> 585 | I106: =F106*5% -> 29.25 | J106: =F106+I106 -> 614.25 | K106: REENA
...

Sheet Summary REA Adv - AR- 25 Mar24
C3: 2024
B4: Client Names | C4: Jan | D4: Feb | E4: Mar | F4: Grand Total
B5: ADIRONDACK ARCHITECTURAL MODELS INDUSTRY L.L.C | D5: 47.62 | F5: =SUM(C5:E5) -> 47.62
B6: Al Naser International FZE | D6: 3150 | F6: =SUM(C6:E6) -> 3150
B7: AL RASHED UNITED DMCC | D7: 3490 | F7: =SUM(C7:E7) -> 3490
B8: Al Tayer Insignia LLC | D8: 10965 | F8: =SUM(C8:E8) -> 10965
B9: Ali Salim Ali Salim Alqaydi | D9: 2715 | F9: =SUM(C9:E9) -> 2715
B10: AMANI INVESTMENTS L.L.C - FZ | C10: 995 | F10: =SUM(C10:E10) -> 995
B11: ANB AUTOMOBILES L.L.C | D11: 1580 | E11: 1130 | F11: =SUM(C11:E11) -> 2710
B12: Aram Precious Metals Trading FZE | C12: 250 | D12: 3150 | F12: =SUM(C12:E12) -> 3400
B13: A-Technologies FZCO | C13: 6050 | F13: =SUM(C13:E13) -> 6050
B14: Aurantius Real Estate Broker | C14: 553.75 | D14: 2410.5 | E14: =+'REA Adv - Invoices'!G191 -> 792.5 | F14: =SUM(C14:E14) -> 3756.75
B15: AUSTRAL INTERNATIONAL DMCC | C15: 745 | D15: 3150 | F15: =SUM(C15:E15) -> 3895
B16: Austral International FZE | C16: 250 | F16: =SUM(C16:E16) -> 250
B17: Bianca and Bianco Trading LLC | C17: 825 | D17: 310 | F17: =SUM(C17:E17) -> 1135
B18: Bin Ghatti | E18: 1725 | F18: =SUM(C18:E18) -> 1725
B19: Blu Orbit | C19: 1250 | F19: =SUM(C19:E19) -> 1250
B20: BorgRollsWarner Middle East LLC | C20: 14375 | F20: =SUM(C20:E20) -> 14375
B21: Byyus Gift Trading | E21: =1925+'REA Adv - Invoices'!G184+'REA Adv - Invoices'!G190 -> 4660 | F21: =SUM(C21:E21) -> 4660
B22: CJ ICM FZCO | C22: 3150 | F22: =SUM(C22:E22) -> 3150
B23: CLARION SCHOOL LLC | C23: 0 | F23: =SUM(C23:E23) -> 0
B24: Continental Middle East DMCC | D24: 3835 | F24: =SUM(C24:E24) -> 3835
B25: Crescent Real Estate | D25: 1920 | F25: =SUM(C25:E25) -> 1920
B26: Dubai Academic Health /MBRU | E26: =+'REA Adv - Invoices'!G186 -> 6920 | F26: =SUM(C26:E26) -> 6920
B27: DUNECREST AMERICAN SCHOOL L.L.C | C27: 19193.5 | F27: =SUM(C27:E27) -> 19193.5
B28: DYNAMIC EMPLOYMENT SERVICES L.L.C | D28: 892.5 | F28: =SUM(C28:E28) -> 892.5
B29: E and S Luxury Car Rental LLC | C29: 300 | F29: =SUM(C29:E29) -> 300
B30: E V OFFSHORE LIMITED (DUBAI BRANCH) | D30: 1400 | F30: =SUM(C30:E30) -> 1400
B31: EMIRATES FOR UNIVERSAL TYRES L.L.C. | C31: 1315 | F31: =SUM(C31:E31) -> 1315
B32: Enara Properties | C32: 95 | F32: =SUM(C32:E32) -> 95
B33: FAD Institute of Luxury Fashion and Style Dubai | C33: 1690 | F33: =SUM(C33:E33) -> 1690
B34: Global Connect | C34: 120 | D34: 190 | F34: =SUM(C34:E34) -> 310
B35: Golden Tower Technologies | D35: 8850 | F35: =SUM(C35:E35) -> 8850
B36: GOOD VIBES TRANSPORT L.L.C | E36: 925 | F36: =SUM(C36:E36) -> 925
B37: Grandmatic Technical | E37: 285 | F37: =SUM(C37:E37) -> 285
B38: GRAND STAR ALUMINUM & GLASS L.L.C | C38: 8360 | F38: =SUM(C38:E38) -> 8360
B39: Griffith College | D39: 1225 | F39: =SUM(C39:E39) -> 1225
B40: GrokGlobal Services | C40: 4475 | E40: 22177.5 | F40: =SUM(C40:E40) -> 26652.5
B41: Gulftainer | E41: =+'REA Adv - Invoices'!G196 -> 2358.75 | F41: =SUM(C41:E41) -> 2358.75
B42: HOLO MORTGAGE CONSULTANT | C42: 1060 | F42: =SUM(C42:E42) -> 1060
...

Sheet For Pivot
B2: CLIENT | C2: INVOICE NO. | D2: INVOICE DATE | E2: CLIENT TRN | F2: DESCRIPTION | G2: INVOICE SUB-TOTAL | H2: REBATE | I2: INVOICE SUB-TOTAL AFTER REBATE | J2: VAT % AMOUNT | K2: TOTAL INVOICE AMOUNT | L2: Sales Person | M2: =COUNTA(C:C)-1 -> 466 | N2: =GETPIVOTDATA("Count of INVOICE NO.",#REF!)+GETPIVOTDATA("Count of INVOICE NO.",#REF!) -> #REF! | O2: =SUM(G:G) -> 1160237.7 | P2: No of invoice
B3: Stellar Advertising LLC | C3: 24-0001 | D3: 45293 | E3: 100542487200003 | F3: A3 Poster - Jebel Ali School | G3: 425.49 | I3: =G3-H3 -> 425.49 | J3: =G3*5% -> 21.2745 | K3: =G3+J3 -> 446.7645 | L3: REENA | P3: 1
B4: Stellar Advertising LLC | C4: 24-0002 | D4: 45295 | E4: 100542487200003 | F4: A5 Booklet - DBSJP (Nov/Dec) | G4: 415 | I4: =G4-H4 -> 415 | J4: =G4*5% -> 20.75 | K4: =G4+J4 -> 435.75 | L4: REENA | P4: 1
B5: Aurantius Real Estate Broker | C5: 24-0003 | D5: 45295 | E5: 104166051300003 | F5: Business Cards ( Ferhat Doghan ) | G5: 475 | I5: =G5-H5 -> 475 | J5: =G5*5% -> 23.75 | K5: =G5+J5 -> 498.75 | L5: REENA | P5: 1
B6: A-Technologies FZCO | C6: 24-0004 | D6: 45306 | E6: 100312976200003 | F6: Water Bottle , A5 Notebook (Anti-Microbial) , Metal Pen , Box | G6: 5850 | I6: =G6-H6 -> 5850 | J6: =G6*5% -> 292.5 | K6: =G6+J6 -> 6142.5 | L6: MARINELLE | P6: 1
B7: EMIRATES FOR UNIVERSAL TYRES L.L.C. | C7: 24-0005 | D7: 45297 | E7: 100032677500003 | F7: Sticker (Paper) | G7: 425 | I7: =G7-H7 -> 425 | J7: =G7*5% -> 21.25 | K7: =G7+J7 -> 446.25 | L7: REENA | P7: 1
B8: GRAND STAR ALUMINUM & GLASS L.L.C | C8: 24-0006 | D8: 45296 | E8: 100522321700003 | F8: Wooden Board | G8: 7600 | I8: =G8-H8 -> 7600 | J8: =G8*5% -> 380 | K8: =G8+J8 -> 7980 | L8: REENA | P8: 1
B9: VISIONARY FURNITURE TRADING L.L.C | C9: 24-0007 | D9: 45302 | E9: 104037069200003 | F9: Business Cards , Polo Shirts | G9: 848 | I9: =G9-H9 -> 848 | J9: =G9*5% -> 42.4 | K9: =G9+J9 -> 890.4 | L9: REENA | P9: 1
B10: Navitas Middle East FZ - LLC | C10: 24-0008 | D10: 45300 | E10: 100430750800003 | F10: Round neck Tshirt | G10: 380 | I10: =G10-H10 -> 380 | J10: =G10*5% -> 19 | K10: =G10+J10 -> 399 | L10: REENA | P10: 1
B11: Trane BVBA (Abu Dhabi) | C11: 24-0009 | D11: 45316 | E11: 100348311000003 | F11: Business Card ( Mohamed Ben Hamouda ) | G11: 405 | I11: =G11-H11 -> 405 | J11: =G11*5% -> 20.25 | K11: =G11+J11 -> 425.25 | L11: REENA | P11: 1
B12: M Y WORLD TRADING L.L.C | C12: 24-0010 | D12: 45300 | E12: 104014963300003 | F12: Business Cards ( Mr. Mehdi M Taki , Mr. Muhammed Midlaj ) | G12: 530 | I12: =G12-H12 -> 530 | J12: =G12*5% -> 26.5 | K12: =G12+J12 -> 556.5 | L12: REENA | P12: 1
B13: GRAND STAR ALUMINUM & GLASS L.L.C | C13: 24-0011 | D13: 45302 | E13: 100522321700003 | F13: Acrylic Stand | G13: 760 | I13: =G13-H13 -> 760 | J13: =G13*5% -> 38 | K13: =G13+J13 -> 798 | L13: REENA | P13: 1
B14: IDP Education Services Nigeria Limited | C14: 24-0012 | D14: 45300 | E14: - | F14: Polo Shirt | G14: =3.67*62.1 -> 227.907 | I14: =G14-H14 -> 227.907 | J14: =G14*5% -> 11.39535 | K14: =G14+J14 -> 239.30235 | L14: REENA | P14: 1
B15: M E A D Medical Supplies & Equipment L.L.C | C15: 24-0013 | D15: 45303 | E15: 100540543400003 | F15: NCR Book | G15: 475 | I15: =G15-H15 -> 475 | J15: =G15*5% -> 23.75 | K15: =G15+J15 -> 498.75 | L15: MARINELLE | P15: 1
B16: Stellar Advertising LLC | C16: 24-0014 | D16: 45303 | E16: 100542487200003 | F16: Poster , Flag ( Raha International School ) | G16: 440 | I16: =G16-H16 -> 440 | J16: =G16*5% -> 22 | K16: =G16+J16 -> 462 | L16: REENA | P16: 1
B17: Lloyds Energy DMCC | C17: 24-0015 | D17: 45303 | E17: 100056728700003 | F17: Signage (Without Light) | G17: 1250 | I17: =G17-H17 -> 1250 | J17: =G17*5% -> 62.5 | K17: =G17+J17 -> 1312.5 | L17: MARINELLE | P17: 1
B18: EMIRATES FOR UNIVERSAL TYRES L.L.C. | C18: 24-0016 | D18: 45303 | E18: 100032677500003 | F18: Business card ( Rineesh Ali ) | G18: 165 | I18: =G18-H18 -> 165 | J18: =G18*5% -> 8.25 | K18: =G18+J18 -> 173.25 | L18: REENA | P18: 1
B19: Bianca and Bianco Trading LLC | C19: 24-0017 | D19: 45304 | E19: 100482284500003 | F19: Business Card | G19: 825 | I19: =G19-H19 -> 825 | J19: =G19*5% -> 41.25 | K19: =G19+J19 -> 866.25 | L19: REENA | P19: 1
B20: Logic Utilities District Cooling Services LLC | C20: 24-0018 | D20: 45316 | E20: 100567483100003 | F20: Polo Shirts | G20: 4252.5 | I20: =G20-H20 -> 4252.5 | J20: =G20*5% -> 212.625 | K20: =G20+J20 -> 4465.125 | L20: MARINELLE | P20: 1
B21: FAD Institute of Luxury Fashion and Style Dubai | C21: 24-0019 | D21: 45307 | E21: - | F21: Certificate Holder | G21: 1690 | I21: =G21-H21 -> 1690 | J21: =G21*5% -> 84.5 | K21: =G21+J21 -> 1774.5 | L21: MARINELLE | P21: 1
B22: Ingersoll-Rand Technical and Services S A R L (Dubai Branch) | C22: 24-0020 | D22: 45306 | E22: 100399495900003 | F22: Business Card | G22: 310 | I22: =G22-H22 -> 310 | J22: =G22*5% -> 15.5 | K22: =G22+J22 -> 325.5 | L22: MARINELLE | P22: 1
B23: JUBAILI BROS S.A.L. | C23: 24-0021 | D23: 45307 | E23: 100293287700003 | F23: Car Sunshades (Tyvek) | G23: 5975 | I23: =G23-H23 -> 5975 | J23: =G23*5% -> 298.75 | K23: =G23+J23 -> 6273.75 | L23: MARINELLE | P23: 1
B24: Global Connect | C24: 24-0022 | D24: 45303 | E24: - | F24: Rubber stamp | G24: 120 | I24: =G24-H24 -> 120 | J24: =G24*5% -> 6 | K24: =G24+J24 -> 126 | L24: REENA | P24: 1
B25: IDP EDUCATION L.L.C | C25: 24-0023 | D25: 45303 | E25: 100593105800003 | F25: Rubber Stamp | G25: 0 | I25: =G25-H25 -> 0 | J25: =G25*5% -> 0 | K25: =G25+J25 -> 0 | L25: REENA | P25: 1
B26: A-Technologies FZCO | C26: 24-0024 | D26: 45307 | E26: 100312976200003 | F26: Prints for Gift Box | G26: 200 | I26: =G26-H26 -> 200 | J26: =G26*5% -> 10 | K26: =G26+J26 -> 210 | L26: MARINELLE | P26: 1
... B95: Trane BVBA (Dubai Branch) | C95: 24-0093 | D95: 45335 | E95: 100235699400003 | F95: Crystal Trophy | G95: 1800 | I95: =G95-H95 -> 1800 | J95: =G95*5% -> 90 | K95: =G95+J95 -> 1890 | L95: REENA | P95: 1
B96: Krishna International FZCO | C96: 24-0094 | D96: 45332 | E96: 100060213400003 | F96: Wedding Luggage Tags | G96: 13000 | I96: =G96-H96 -> 13000 | J96: =G96*5% -> 650 | K96: =G96+J96 -> 13650 | L96: REENA | P96: 1
B97: One Blue Clover FZCO | C97: 24-0095 | D97: 45338 | E97: - | F97: Letterhead | G97: 525 | I97: =G97-H97 -> 525 | J97: =G97*5% -> 26.25 | K97: =G97+J97 -> 551.25 | L97: REENA | P97: 1
B98: Stellar Advertising LLC | C98: 24-0096 | D98: 45337 | E98: 100542487200003 | F98: Selfie Frame - DBSJP , Prop - #Outstanding | G98: 595 | I98: =G98-H98 -> 595 | J98: =G98*5% -> 29.75 | K98: =G98+J98 -> 624.75 | L98: REENA | P98: 1
B99: Stellar Advertising LLC | C99: 24-0097 | D99: 45338 | E99: 100542487200003 | F99: Roll Up - AAG | G99: 145 | I99: =G99-H99 -> 145 | J99: =G99*5% -> 7.25 | K99: =G99+J99 -> 152.25 | L99: REENA | P99: 1
B100: M E A D Medical Supplies & Equipment L.L.C | C100: 24-0098 | D100: 45341 | E100: 100540543400003 | F100: NCR Book , Business Cards | G100: 860 | I100: =G100-H100 -> 860 | J100: =G100*5% -> 43 | K100: =G100+J100 -> 903 | L100: MARINELLE | P100: 1
B101: Stellar Advertising LLC | C101: 24-0099 | D101: 45342 | E101: 100542487200003 | F101: Letterhead - FICHTE | G101: 625 | I101: =G101-H101 -> 625 | J101: =G101*5% -> 31.25 | K101: =G101+J101 -> 656.25 | L101: REENA | P101: 1
B102: Golden Tower Technologies | C102: 24-0100 | D102: 45338 | E102: 100470289800003 | F102: Flex to be changed for existing light box | G102: 8850 | I102: =G102-H102 -> 8850 | J102: =G102*5% -> 442.5 | K102: =G102+J102 -> 9292.5 | L102: REENA | P102: 1
B103: Thermo Fisher Scientific S.P.A. | C103: 24-0101 | D103: 45338 | E103: IT 07817950152 | F103: Flyer , Recycled 6-in-1 Charging Cable | G103: 3335 | I103: =G103-H103 -> 3335 | J103: =G103*5% -> 166.75 | K103: =G103+J103 -> 3501.75 | L103: MARINELLE | P103: 1
B104: Griffith College | C104: 24-0102 | D104: 45338 | E104: - | F104: Brochure | G104: 1225 | I104: =G104-H104 -> 1225 | J104: =G104*5% -> 61.25 | K104: =G104+J104 -> 1286.25 | L104: REENA | P104: 1
B105: IDP EDUCATION L.L.C | C105: 24-0103 | D105: 45341 | E105: 100593105800003 | F105: Dubai Roadshow Millenium Downtown, 17th Feb 2024 | G105: 103245.5 | I105: =G105-H105 -> 103245.5 | J105: =G105*5% -> 5162.275 | K105: =G105+J105 -> 108407.77 | L105: REENA | P105: 1
B106: IDP EDUCATION L.L.C | C106: 24-0104 | D106: 45341 | E106: 100593105800003 | F106: Abu Dhabi Roadshow 18 Feb 2024, InterContinental | G106: 51717.75 | I106: =G106-H106 -> 51717.75 | J106: =G106*5% -> 2585.8875 | K106: =G106+J106 -> 54303.637 | L106: REENA | P106: 1
B107: DYNAMIC EMPLOYMENT SERVICES L.L.C | C107: 24-0105 | D107: 45343 | E107: 100323347300003 | F107: Parking Signage | G107: 892.5 | I107: =G107-H107 -> 892.5 | J107: =G107*5% -> 44.625 | K107: =G107+J107 -> 937.125 | L107: MARINELLE | P107: 1
B108: Stellar Advertising LLC | C108: 24-0106 | D108: 45343 | E108: 100542487200003 | F108: Flyer - Taylor Wessing | G108: 190 | I108: =G108-H108 -> 190 | J108: =G108*5% -> 9.5 | K108: =G108+J108 -> 199.5 | L108: REENA | P108: 1
B109: Stellar Advertising LLC | C109: 24-0107 | D109: 45342 | E109: 100542487200003 | F109: Journal - DBSEH | G109: 585 | I109: =G109-H109 -> 585 | J109: =G109*5% -> 29.25 | K109: =G109+J109 -> 614.25 | L109: REENA | P109: 1
...

Sheet calc
B2: CLIENT | C2: INVOICE NO. | D2: INVOICE DATE | E2: CLIENT TRN | F2: DESCRIPTION | G2: INVOICE SUB-TOTAL | H2: REBATE | I2: INVOICE SUB-TOTAL AFTER REBATE | J2: VAT % AMOUNT | K2: TOTAL INVOICE AMOUNT | L2: Sales Person | M2: =COUNTA(C:C)-1 -> 404 | N2: =GETPIVOTDATA("Count of INVOICE NO.",#REF!)+GETPIVOTDATA("Count of INVOICE NO.",#REF!) -> #REF! | O2: =SUM(G:G) -> 1049942.5 | P2: No of invoice
B3: Stellar Advertising LLC | C3: 24-0001 | D3: 45293 | E3: 100542487200003 | F3: A3 Poster - Jebel Ali School | G3: 425.49 | I3: =G3-H3 -> 425.49 | J3: =G3*5% -> 21.2745 | K3: =G3+J3 -> 446.7645 | L3: REENA | P3: 1
B4: Stellar Advertising LLC | C4: 24-0002 | D4: 45295 | E4: 100542487200003 | F4: A5 Booklet - DBSJP (Nov/Dec) | G4: 415 | I4: =G4-H4 -> 415 | J4: =G4*5% -> 20.75 | K4: =G4+J4 -> 435.75 | L4: REENA | P4: 1
B5: Aurantius Real Estate Broker | C5: 24-0003 | D5: 45295 | E5: 104166051300003 | F5: Business Cards ( Ferhat Doghan ) | G5: 475 | I5: =G5-H5 -> 475 | J5: =G5*5% -> 23.75 | K5: =G5+J5 -> 498.75 | L5: REENA | P5: 1
B6: A-Technologies FZCO | C6: 24-0004 | D6: 45306 | E6: 100312976200003 | F6: Water Bottle , A5 Notebook (Anti-Microbial) , Metal Pen , Box | G6: 5850 | I6: =G6-H6 -> 5850 | J6: =G6*5% -> 292.5 | K6: =G6+J6 -> 6142.5 | L6: MARINELLE | P6: 1
B7: EMIRATES FOR UNIVERSAL TYRES L.L.C. | C7: 24-0005 | D7: 45297 | E7: 100032677500003 | F7: Sticker (Paper) | G7: 425 | I7: =G7-H7 -> 425 | J7: =G7*5% -> 21.25 | K7: =G7+J7 -> 446.25 | L7: REENA | P7: 1
B8: GRAND STAR ALUMINUM & GLASS L.L.C | C8: 24-0006 | D8: 45296 | E8: 100522321700003 | F8: Wooden Board | G8: 7600 | I8: =G8-H8 -> 7600 | J8: =G8*5% -> 380 | K8: =G8+J8 -> 7980 | L8: REENA | P8: 1
B9: VISIONARY FURNITURE TRADING L.L.C | C9: 24-0007 | D9: 45302 | E9: 104037069200003 | F9: Business Cards , Polo Shirts | G9: 848 | I9: =G9-H9 -> 848 | J9: =G9*5% -> 42.4 | K9: =G9+J9 -> 890.4 | L9: REENA | P9: 1
B10: Navitas Middle East FZ - LLC | C10: 24-0008 | D10: 45300 | E10: 100430750800003 | F10: Round neck Tshirt | G10: 380 | I10: =G10-H10 -> 380 | J10: =G10*5% -> 19 | K10: =G10+J10 -> 399 | L10: REENA | P10: 1
B11: Trane BVBA (Dubai Branch) | C11: 24-0009 | D11: 45316 | E11: 100348311000003 | F11: Business Card ( Mohamed Ben Hamouda ) | G11: 405 | I11: =G11-H11 -> 405 | J11: =G11*5% -> 20.25 | K11: =G11+J11 -> 425.25 | L11: REENA | P11: 1
B12: M Y WORLD TRADING L.L.C | C12: 24-0010 | D12: 45300 | E12: 104014963300003 | F12: Business Cards ( Mr. Mehdi M Taki , Mr. Muhammed Midlaj ) | G12: 530 | I12: =G12-H12 -> 530 | J12: =G12*5% -> 26.5 | K12: =G12+J12 -> 556.5 | L12: REENA | P12: 1
B13: GRAND STAR ALUMINUM & GLASS L.L.C | C13: 24-0011 | D13: 45302 | E13: 100522321700003 | F13: Acrylic Stand | G13: 760 | I13: =G13-H13 -> 760 | J13: =G13*5% -> 38 | K13: =G13+J13 -> 798 | L13: REENA | P13: 1
B14: IDP EDUCATION L.L.C | C14: 24-0012 | D14: 45300 | E14: - | F14: Polo Shirt | G14: =3.67*62.1 -> 227.907 | I14: =G14-H14 -> 227.907 | J14: =G14*5% -> 11.39535 | K14: =G14+J14 -> 239.30235 | L14: REENA | P14: 1
B15: M E A D Medical Supplies & Equipment L.L.C | C15: 24-0013 | D15: 45303 | E15: 100540543400003 | F15: NCR Book | G15: 475 | I15: =G15-H15 -> 475 | J15: =G15*5% -> 23.75 | K15: =G15+J15 -> 498.75 | L15: MARINELLE | P15: 1
B16: Stellar Advertising LLC | C16: 24-0014 | D16: 45303 | E16: 100542487200003 | F16: Poster , Flag ( Raha International School ) | G16: 440 | I16: =G16-H16 -> 440 | J16: =G16*5% -> 22 | K16: =G16+J16 -> 462 | L16: REENA | P16: 1
B17: Lloyds Energy DMCC | C17: 24-0015 | D17: 45303 | E17: 100056728700003 | F17: Signage (Without Light) | G17: 1250 | I17: =G17-H17 -> 1250 | J17: =G17*5% -> 62.5 | K17: =G17+J17 -> 1312.5 | L17: MARINELLE | P17: 1
B18: EMIRATES FOR UNIVERSAL TYRES L.L.C. | C18: 24-0016 | D18: 45303 | E18: 100032677500003 | F18: Business card ( Rineesh Ali ) | G18: 165 | I18: =G18-H18 -> 165 | J18: =G18*5% -> 8.25 | K18: =G18+J18 -> 173.25 | L18: REENA | P18: 1
B19: Bianca and Bianco Trading LLC | C19: 24-0017 | D19: 45304 | E19: 100482284500003 | F19: Business Card | G19: 825 | I19: =G19-H19 -> 825 | J19: =G19*5% -> 41.25 | K19: =G19+J19 -> 866.25 | L19: REENA | P19: 1
B20: Logic Utilities District Cooling Services LLC | C20: 24-0018 | D20: 45316 | E20: 100567483100003 | F20: Polo Shirts | G20: 4252.5 | I20: =G20-H20 -> 4252.5 | J20: =G20*5% -> 212.625 | K20: =G20+J20 -> 4465.125 | L20: MARINELLE | P20: 1
B21: FAD Institute of Luxury Fashion and Style Dubai | C21: 24-0019 | D21: 45307 | E21: - | F21: Certificate Holder | G21: 1690 | I21: =G21-H21 -> 1690 | J21: =G21*5% -> 84.5 | K21: =G21+J21 -> 1774.5 | L21: MARINELLE | P21: 1
B22: Ingersoll-Rand Technical and Services S A R L (Dubai Branch) | C22: 24-0020 | D22: 45306 | E22: 100399495900003 | F22: Business Card | G22: 310 | I22: =G22-H22 -> 310 | J22: =G22*5% -> 15.5 | K22: =G22+J22 -> 325.5 | L22: MARINELLE | P22: 1
B23: JUBAILI BROS S.A.L. | C23: 24-0021 | D23: 45307 | E23: 100293287700003 | F23: Car Sunshades (Tyvek) | G23: 5975 | I23: =G23-H23 -> 5975 | J23: =G23*5% -> 298.75 | K23: =G23+J23 -> 6273.75 | L23: MARINELLE | P23: 1
B24: Global Connect | C24: 24-0022 | D24: 45303 | E24: - | F24: Rubber stamp | G24: 120 | I24: =G24-H24 -> 120 | J24: =G24*5% -> 6 | K24: =G24+J24 -> 126 | L24: REENA | P24: 1
B25: IDP EDUCATION L.L.C | C25: 24-0023 | D25: 45303 | E25: 100593105800003 | F25: Rubber Stamp | G25: 0 | I25: =G25-H25 -> 0 | J25: =G25*5% -> 0 | K25: =G25+J25 -> 0 | L25: REENA | P25: 1
B26: A-Technologies FZCO | C26: 24-0024 | D26: 45307 | E26: 100312976200003 | F26: Prints for Gift Box | G26: 200 | I26: =G26-H26 -> 200 | J26: =G26*5% -> 10 | K26: =G26+J26 -> 210 | L26: MARINELLE | P26: 1
... B95: Trane BVBA (Dubai Branch) | C95: 24-0093 | D95: 45335 | E95: 100235699400003 | F95: Crystal Trophy | G95: 1800 | I95: =G95-H95 -> 1800 | J95: =G95*5% -> 90 | K95: =G95+J95 -> 1890 | L95: REENA | P95: 1
B96: Krishna International FZCO | C96: 24-0094 | D96: 45332 | E96: 100060213400003 | F96: Wedding Luggage Tags | G96: 13000 | I96: =G96-H96 -> 13000 | J96: =G96*5% -> 650 | K96: =G96+J96 -> 13650 | L96: REENA | P96: 1
B97: One Blue Clover FZCO | C97: 24-0095 | D97: 45338 | E97: - | F97: Letterhead | G97: 525 | I97: =G97-H97 -> 525 | J97: =G97*5% -> 26.25 | K97: =G97+J97 -> 551.25 | L97: REENA | P97: 1
B98: Stellar Advertising LLC | C98: 24-0096 | D98: 45337 | E98: 100542487200003 | F98: Selfie Frame - DBSJP , Prop - #Outstanding | G98: 595 | I98: =G98-H98 -> 595 | J98: =G98*5% -> 29.75 | K98: =G98+J98 -> 624.75 | L98: REENA | P98: 1
B99: Stellar Advertising LLC | C99: 24-0097 | D99: 45338 | E99: 100542487200003 | F99: Roll Up - AAG | G99: 145 | I99: =G99-H99 -> 145 | J99: =G99*5% -> 7.25 | K99: =G99+J99 -> 152.25 | L99: REENA | P99: 1
B100: M E A D Medical Supplies & Equipment L.L.C | C100: 24-0098 | D100: 45341 | E100: 100540543400003 | F100: NCR Book , Business Cards | G100: 860 | I100: =G100-H100 -> 860 | J100: =G100*5% -> 43 | K100: =G100+J100 -> 903 | L100: MARINELLE | P100: 1
B101: Stellar Advertising LLC | C101: 24-0099 | D101: 45342 | E101: 100542487200003 | F101: Letterhead - FICHTE | G101: 625 | I101: =G101-H101 -> 625 | J101: =G101*5% -> 31.25 | K101: =G101+J101 -> 656.25 | L101: REENA | P101: 1
B102: Golden Tower Technologies | C102: 24-0100 | D102: 45338 | E102: 100470289800003 | F102: Flex to be changed for existing light box | G102: 8850 | I102: =G102-H102 -> 8850 | J102: =G102*5% -> 442.5 | K102: =G102+J102 -> 9292.5 | L102: REENA | P102: 1
B103: Thermo Fisher Scientific S.P.A. | C103: 24-0101 | D103: 45338 | E103: IT 07817950152 | F103: Flyer , Recycled 6-in-1 Charging Cable | G103: 3335 | I103: =G103-H103 -> 3335 | J103: =G103*5% -> 166.75 | K103: =G103+J103 -> 3501.75 | L103: MARINELLE | P103: 1
B104: Griffith College | C104: 24-0102 | D104: 45338 | E104: - | F104: Brochure | G104: 1225 | I104: =G104-H104 -> 1225 | J104: =G104*5% -> 61.25 | K104: =G104+J104 -> 1286.25 | L104: REENA | P104: 1
B105: IDP EDUCATION L.L.C | C105: 24-0103 | D105: 45341 | E105: 100593105800003 | F105: Dubai Roadshow Millenium Downtown, 17th Feb 2024 | G105: 103245.5 | I105: =G105-H105 -> 103245.5 | J105: =G105*5% -> 5162.275 | K105: =G105+J105 -> 108407.77 | L105: REENA | P105: 1
B106: IDP EDUCATION L.L.C | C106: 24-0104 | D106: 45341 | E106: 100593105800003 | F106: Abu Dhabi Roadshow 18 Feb 2024, InterContinental | G106: 51717.75 | I106: =G106-H106 -> 51717.75 | J106: =G106*5% -> 2585.8875 | K106: =G106+J106 -> 54303.637 | L106: REENA | P106: 1
B107: DYNAMIC EMPLOYMENT SERVICES L.L.C | C107: 24-0105 | D107: 45343 | E107: 100323347300003 | F107: Parking Signage | G107: 892.5 | I107: =G107-H107 -> 892.5 | J107: =G107*5% -> 44.625 | K107: =G107+J107 -> 937.125 | L107: MARINELLE | P107: 1
B108: Stellar Advertising LLC | C108: 24-0106 | D108: 45343 | E108: 100542487200003 | F108: Flyer - Taylor Wessing | G108: 190 | I108: =G108-H108 -> 190 | J108: =G108*5% -> 9.5 | K108: =G108+J108 -> 199.5 | L108: REENA | P108: 1
B109: Stellar Advertising LLC | C109: 24-0107 | D109: 45342 | E109: 100542487200003 | F109: Journal - DBSEH | G109: 585 | I109: =G109-H109 -> 585 | J109: =G109*5% -> 29.25 | K109: =G109+J109 -> 614.25 | L109: REENA | P109: 1
...

Sheet Summary REA Adv
A3: Sum of INVOICE SUB-TOTAL | B3: Month | E3: Sum of INVOICE SUB-TOTAL | F3: Month | J3: Sum of INVOICE SUB-TOTAL | K3: Month
A4: Client Name | B4: Jun | C4: Grand Total | E4: Client Name | F4: Jul | G4: Grand Total | J4: Client Name | K4: Jan | L4: Feb | M4: Mar | N4: Apr | O4: May | P4: Jun | Q4: Jul | R4: Aug | S4: Grand Total
A5: Al Naser International FZE | B5: 485 | C5: 485 | E5: Al Naser International FZE | F5: 287.5 | G5: 287.5 | J5: GLEN | K5: 6081 | S5: 6081
A6: ANB AUTOMOBILES L.L.C | B6: 389.75 | C6: 389.75 | E6: AL RASHED UNITED DMCC | F6: 1395 | G6: 1395 | J6: MARINELLE | K6: 68501.24 | L6: 36948 | M6: 52520.87 | N6: 66984.5 | O6: 48692.26 | P6: 99968.08 | Q6: 51732.2 | R6: 1580 | S6: 426927.15
A7: Aurantius Real Estate Broker | B7: 2138 | C7: 2138 | E7: Aurantius Real Estate Broker | F7: 1000 | G7: 1000 | J7: PROFORMA | P7: 39130 | Q7: 13786.81 | S7: 52916.81
A8: Byyu Gift Trading LLC | B8: 5935 | C8: 5935 | E8: AUSTRAL INTERNATIONAL DMCC | F8: 287.5 | G8: 287.5 | J8: REENA | K8: 76931.497 | L8: 230704.47 | M8: 71536 | N8: 27060.45 | O8: 83866.69 | P8: 138844.77 | Q8: 39127.58 | S8: 668071.46
A9: Continental Middle East DMCC | B9: 3086 | C9: 3086 | E9: Bianca and Bianco Trading LLC | F9: 3210 | G9: 3210 | J9: BNI | P9: 999.29 | Q9: 1492 | S9: 2491.29
A10: Dubai Academic Health Corporation (DAHC) | B10: 24338.5 | C10: 24338.5 | E10: BorgRollsWarner Middle East LLC | F10: 1933.5 | G10: 1933.5 | J10: GAGANDEEP | P10: 0 | Q10: 3750 | S10: 3750
A11: DUNECREST AMERICAN SCHOOL L.L.C | B11: 358.75 | C11: 358.75 | E11: Byyu Gift Trading LLC | F11: 485 | G11: 485 | J11: Grand Total | K11: 151513.74 | L11: 267652.47 | M11: 124056.87 | N11: 94044.95 | O11: 132558.95 | P11: 278942.14 | Q11: 109888.59 | R11: 1580 | S11: 1160237.7
A12: Global Connect | B12: 820 | C12: 820 | E12: Continental Middle East DMCC | F12: 5528.75 | G12: 5528.75
A13: GrokGlobal Services | B13: 6445 | C13: 6445 | E13: DUNECREST AMERICAN SCHOOL L.L.C | F13: 14110 | G13: 14110
A14: Huxley Associates Global Limited | B14: 1233.75 | C14: 1233.75 | E14: GrokGlobal Services | F14: 275 | G14: 275
A15: IDP EDUCATION L.L.C | B15: 160 | C15: 160 | E15: IDP EDUCATION L.L.C | F15: 5885 | G15: 5885
A16: Ingersoll-Rand Technical and Services S A R L (Dubai Branch) | B16: 285 | C16: 285 | E16: Indo Tausch Trading DMCC | F16: 125 | G16: 125
A17: Lloyds Energy DMCC | B17: 870 | C17: 870 | E17: J C S ARTIFICIAL FLOWERS & PLANTS TRADING L.L.C | F17: 2435 | G17: 2435
A18: M E A D Medical Supplies & Equipment L.L.C | B18: 10070 | C18: 10070 | E18: Lloyds Energy DMCC | F18: 3110 | G18: 3110
A19: Navitas Middle East FZ - LLC | B19: 33682.5 | C19: 33682.5 | E19: Logic Utilities District Cooling Services LLC | F19: 700 | G19: 700
A20: Navitas SAE FZ-LLC | B20: 1325 | C20: 1325 | E20: Navitas Middle East FZ - LLC | F20: 977 | G20: 977
A21: SPH Global Holdings LLC | B21: 210 | C21: 210 | E21: Stellar Advertising LLC | F21: 15382.81 | G21: 15382.81
A22: Stellar Advertising LLC | B22: 76627.75 | C22: 76627.75 | E22: Trane BVBA (Abu Dhabi) | F22: 760 | G22: 760
A23: The Woolwich Institute | B23: 735 | C23: 735 | E23: Trane BVBA (Dubai Branch) | F23: 4369 | G23: 4369
... A41: Grand Total | B41: 278942.14 | C41: 278942.14 | E41: BLUE TANGERINE MARKETING MANAGEMENT | F41: 3750 | G41: 3750
E42: Locke Lifestyle Properties | F42: 1600 | G42: 1600
E43: IBM Global Middle East FZCO | F43: 333.33 | G43: 333.33
E44: Grand Total | F44: 109888.59 | G44: 109888.59

Sheet Sheet2
B3: Column Labels
B4: Jan | D4: Feb | F4: Mar | H4: Apr | J4: May | L4: Jun | N4: Total Sum of INVOICE SUB-TOTAL | O4: Total Sum of No of invoice
A5: Row Labels | B5: Sum of INVOICE SUB-TOTAL | C5: Sum of No of invoice | D5: Sum of INVOICE SUB-TOTAL | E5: Sum of No of invoice | F5: Sum of INVOICE SUB-TOTAL | G5: Sum of No of invoice | H5: Sum of INVOICE SUB-TOTAL | I5: Sum of No of invoice | J5: Sum of INVOICE SUB-TOTAL | K5: Sum of No of invoice | L5: Sum of INVOICE SUB-TOTAL | M5: Sum of No of invoice
A6: ADIRONDACK ARCHITECTURAL MODELS INDUSTRY L.L.C | D6: 47.62 | E6: 1 | N6: 47.62 | O6: 1
A7: Al Naser International FZE | D7: 3150 | E7: 2 | J7: 260 | K7: 1 | N7: 3410 | O7: 3
A8: AL RASHED UNITED DMCC | D8: 3490 | E8: 1 | N8: 3490 | O8: 1
A9: AL SHEMAIL GAR. & PERFUMES TR LLC | J9: 350 | K9: 1 | N9: 350 | O9: 1
A10: Al Tayer Insignia LLC | D10: 10965 | E10: 1 | N10: 10965 | O10: 1
A11: AL WASEEF INDUSTRIES LLC | H11: 380 | I11: 1 | N11: 380 | O11: 1
A12: Ali Salim Ali Salim Alqaydi | D12: 2715 | E12: 1 | N12: 2715 | O12: 1
A13: AMANI INVESTMENTS L.L.C - FZ | B13: 995 | C13: 1 | N13: 995 | O13: 1
A14: ANB AUTOMOBILES L.L.C | D14: 1580 | E14: 1 | F14: 1130 | G14: 1 | N14: 2710 | O14: 2
A15: Aplus Global FZE LLC | H15: 202.95 | I15: 1 | J15: 195 | K15: 1 | N15: 397.95 | O15: 2
A16: Aram Precious Metals Trading FZE | B16: 250 | C16: 1 | D16: 3150 | E16: 2 | J16: 85 | K16: 1 | N16: 3485 | O16: 4
A17: A-Technologies FZCO | B17: 6050 | C17: 2 | N17: 6050 | O17: 2
A18: Aurantius Real Estate Broker | B18: 553.75 | C18: 2 | D18: 2410.5 | E18: 2 | F18: 792.5 | G18: 1 | J18: 869 | K18: 1 | L18: 1788 | M18: 1 | N18: 6413.75 | O18: 7
A19: AUSTRAL INTERNATIONAL DMCC | B19: 745 | C19: 1 | D19: 3150 | E19: 2 | N19: 3895 | O19: 3
A20: Austral International FZE | B20: 250 | C20: 1 | N20: 250 | O20: 1
A21: Azalee Flower Boutique Limited | J21: 8385 | K21: 1 | N21: 8385 | O21: 1
A22: BECKMAN COULTER INTERNATIONAL S.A. (DUBAI BR) | J22: 2173.75 | K22: 1 | N22: 2173.75 | O22: 1
A23: Bianca and Bianco Trading LLC | B23: 825 | C23: 1 | D23: 310 | E23: 1 | H23: 825 | I23: 1 | N23: 1960 | O23: 3
A24: BinGhatti | F24: 1725 | G24: 1 | N24: 1725 | O24: 1
A25: Black Swan Business Setup Services LLC | H25: 285.5 | I25: 1 | N25: 285.5 | O25: 1
A26: Blu Orbit | B26: 1250 | C26: 1 | N26: 1250 | O26: 1
A27: BorgRollsWarner Middle East LLC | B27: 14375 | C27: 1 | N27: 14375 | O27: 1
A28: Byyu Gift Trading LLC | F28: 4225 | G28: 2 | J28: 350 | K28: 1 | N28: 4575 | O28: 3
A29: CACOGES | H29: 2850 | I29: 1 | N29: 2850 | O29: 1
A30: CJ ICM FZCO | B30: 3150 | C30: 1 | N30: 3150 | O30: 1
A31: CLARION SCHOOL LLC | B31: 0 | C31: 1 | N31: 0 | O31: 1
A32: Continental Middle East DMCC | D32: 3835 | E32: 2 | J32: 1266 | K32: 1 | N32: 5101 | O32: 3
A33: Crescent Real Estate | D33: 1920 | E33: 1 | N33: 1920 | O33: 1
A34: DHR MENA FZ-LLC | H34: 29332.5 | I34: 2 | N34: 29332.5 | O34: 2
A35: Dubai Academic Health Corporation (DAHC) | F35: 6920 | G35: 1 | J35: 12375 | K35: 1 | N35: 19295 | O35: 2
A36: DUNECREST AMERICAN SCHOOL L.L.C | B36: 19193.5 | C36: 2 | J36: 3831.3 | K36: 4 | L36: 358.75 | M36: 1 | N36: 23383.55 | O36: 7
A37: DYNAMIC EMPLOYMENT SERVICES L.L.C | D37: 892.5 | E37: 1 | N37: 892.5 | O37: 1
A38: E and S Luxury Car Rental LLC | B38: 300 | C38: 1 | N38: 300 | O38: 1
A39: E V OFFSHORE LIMITED (DUBAI BRANCH) | D39: 1400 | E39: 1 | J39: 944 | K39: 1 | N39: 2344 | O39: 2
A40: Ecotag | J40: 285.71 | K40: 1 | N40: 285.71 | O40: 1
A41: EMIRATES FOR UNIVERSAL TYRES L.L.C. | B41: 1315 | C41: 3 | J41: 450 | K41: 1 | N41: 1765 | O41: 4
A42: Enara Properties | B42: 95 | C42: 1 | N42: 95 | O42: 1
...

Sheet REA Adv - Invoices
B2: CLIENT | C2: INVOICE NO. | D2: INVOICE DATE | E2: CLIENT TRN | F2: DESCRIPTION | G2: INVOICE SUB-TOTAL | H2: REBATE | I2: INVOICE SUB-TOTAL AFTER REBATE | J2: VAT % AMOUNT | K2: TOTAL INVOICE AMOUNT | L2: Sales Person | M2: =COUNTA(C:C)-1 -> 842 | N2: =GETPIVOTDATA("Count of INVOICE NO.",#REF!)+GETPIVOTDATA("Count of INVOICE NO.",#REF!) -> #REF! | O2: =SUM(G:G) -> 2220393.1
B3: Stellar Advertising LLC | C3: 24-0001 | D3: 45293 | E3: 100542487200003 | F3: A3 Poster - Jebel Ali School | G3: 425.49 | I3: =G3-H3 -> 425.49 | J3: =G3*5% -> 21.2745 | K3: =G3+J3 -> 446.7645 | L3: REENA
B4: Stellar Advertising LLC | C4: 24-0002 | D4: 45295 | E4: 100542487200003 | F4: A5 Booklet - DBSJP (Nov/Dec) | G4: 415 | I4: =G4-H4 -> 415 | J4: =G4*5% -> 20.75 | K4: =G4+J4 -> 435.75 | L4: REENA
B5: Aurantius Real Estate Broker | C5: 24-0003 | D5: 45295 | E5: 104166051300003 | F5: Business Cards ( Ferhat Doghan ) | G5: 475 | I5: =G5-H5 -> 475 | J5: =G5*5% -> 23.75 | K5: =G5+J5 -> 498.75 | L5: REENA
B6: A-Technologies FZCO | C6: 24-0004 | D6: 45306 | E6: 100312976200003 | F6: Water Bottle , A5 Notebook (Anti-Microbial) , Metal Pen , Box | G6: 5850 | I6: =G6-H6 -> 5850 | J6: =G6*5% -> 292.5 | K6: =G6+J6 -> 6142.5 | L6: MARINELLE
B7: EMIRATES FOR UNIVERSAL TYRES L.L.C. | C7: 24-0005 | D7: 45297 | E7: 100032677500003 | F7: Sticker (Paper) | G7: 425 | I7: =G7-H7 -> 425 | J7: =G7*5% -> 21.25 | K7: =G7+J7 -> 446.25 | L7: REENA
B8: GRAND STAR ALUMINUM & GLASS L.L.C | C8: 24-0006 | D8: 45296 | E8: 100522321700003 | F8: Wooden Board | G8: 7600 | I8: =G8-H8 -> 7600 | J8: =G8*5% -> 380 | K8: =G8+J8 -> 7980 | L8: REENA
B9: VISIONARY FURNITURE TRADING L.L.C | C9: 24-0007 | D9: 45302 | E9: 104037069200003 | F9: Business Cards , Polo Shirts | G9: 848 | I9: =G9-H9 -> 848 | J9: =G9*5% -> 42.4 | K9: =G9+J9 -> 890.4 | L9: REENA
B10: Navitas Middle East FZ - LLC | C10: 24-0008 | D10: 45300 | E10: 100430750800003 | F10: Round neck Tshirt | G10: 380 | I10: =G10-H10 -> 380 | J10: =G10*5% -> 19 | K10: =G10+J10 -> 399 | L10: REENA
B11: Trane BVBA (Abu Dhabi) | C11: 24-0009 | D11: 45316 | E11: 100348311000003 | F11: Business Card ( Mohamed Ben Hamouda ) | G11: 405 | I11: =G11-H11 -> 405 | J11: =G11*5% -> 20.25 | K11: =G11+J11 -> 425.25 | L11: REENA
B12: M Y WORLD TRADING L.L.C | C12: 24-0010 | D12: 45300 | E12: 104014963300003 | F12: Business Cards ( Mr. Mehdi M Taki , Mr. Muhammed Midlaj ) | G12: 530 | I12: =G12-H12 -> 530 | J12: =G12*5% -> 26.5 | K12: =G12+J12 -> 556.5 | L12: REENA
B13: GRAND STAR ALUMINUM & GLASS L.L.C | C13: 24-0011 | D13: 45302 | E13: 100522321700003 | F13: Acrylic Stand | G13: 760 | I13: =G13-H13 -> 760 | J13: =G13*5% -> 38 | K13: =G13+J13 -> 798 | L13: REENA
B14: IDP Education Services Nigeria Limited | C14: 24-0012 | D14: 45300 | E14: - | F14: Polo Shirt | G14: =3.67*62.1 -> 227.907 | I14: =G14-H14 -> 227.907 | J14: =G14*5% -> 11.39535 | K14: =G14+J14 -> 239.30235 | L14: REENA
B15: M E A D Medical Supplies & Equipment L.L.C | C15: 24-0013 | D15: 45303 | E15: 100540543400003 | F15: NCR Book | G15: 475 | I15: =G15-H15 -> 475 | J15: =G15*5% -> 23.75 | K15: =G15+J15 -> 498.75 | L15: MARINELLE
B16: Stellar Advertising LLC | C16: 24-0014 | D16: 45303 | E16: 100542487200003 | F16: Poster , Flag ( Raha International School ) | G16: 440 | I16: =G16-H16 -> 440 | J16: =G16*5% -> 22 | K16: =G16+J16 -> 462 | L16: REENA
B17: Lloyds Energy DMCC | C17: 24-0015 | D17: 45303 | E17: 100056728700003 | F17: Signage (Without Light) | G17: 1250 | I17: =G17-H17 -> 1250 | J17: =G17*5% -> 62.5 | K17: =G17+J17 -> 1312.5 | L17: MARINELLE
B18: EMIRATES FOR UNIVERSAL TYRES L.L.C. | C18: 24-0016 | D18: 45303 | E18: 100032677500003 | F18: Business card ( Rineesh Ali ) | G18: 165 | I18: =G18-H18 -> 165 | J18: =G18*5% -> 8.25 | K18: =G18+J18 -> 173.25 | L18: REENA
B19: Bianca and Bianco Trading LLC | C19: 24-0017 | D19: 45304 | E19: 100482284500003 | F19: Business Card | G19: 825 | I19: =G19-H19 -> 825 | J19: =G19*5% -> 41.25 | K19: =G19+J19 -> 866.25 | L19: REENA
B20: Logic Utilities District Cooling Services LLC | C20: 24-0018 | D20: 45316 | E20: 100567483100003 | F20: Polo Shirts | G20: 4252.5 | I20: =G20-H20 -> 4252.5 | J20: =G20*5% -> 212.625 | K20: =G20+J20 -> 4465.125 | L20: MARINELLE
B21: FAD Institute of Luxury Fashion and Style Dubai | C21: 24-0019 | D21: 45307 | E21: - | F21: Certificate Holder | G21: 1690 | I21: =G21-H21 -> 1690 | J21: =G21*5% -> 84.5 | K21: =G21+J21 -> 1774.5 | L21: MARINELLE
B22: Ingersoll-Rand Technical and Services S A R L (Dubai Branch) | C22: 24-0020 | D22: 45306 | E22: 100399495900003 | F22: Business Card | G22: 310 | I22: =G22-H22 -> 310 | J22: =G22*5% -> 15.5 | K22: =G22+J22 -> 325.5 | L22: MARINELLE
B23: JUBAILI BROS S.A.L. | C23: 24-0021 | D23: 45307 | E23: 100293287700003 | F23: Car Sunshades (Tyvek) | G23: 5975 | I23: =G23-H23 -> 5975 | J23: =G23*5% -> 298.75 | K23: =G23+J23 -> 6273.75 | L23: MARINELLE
B24: Global Connect | C24: 24-0022 | D24: 45303 | E24: - | F24: Rubber stamp | G24: 120 | I24: =G24-H24 -> 120 | J24: =G24*5% -> 6 | K24: =G24+J24 -> 126 | L24: REENA
B25: IDP EDUCATION L.L.C | C25: 24-0023 | D25: 45303 | E25: 100593105800003 | F25: Rubber Stamp | G25: 0 | I25: =G25-H25 -> 0 | J25: =G25*5% -> 0 | K25: =G25+J25 -> 0 | L25: REENA
B26: A-Technologies FZCO | C26: 24-0024 | D26: 45307 | E26: 100312976200003 | F26: Prints for Gift Box | G26: 200 | I26: =G26-H26 -> 200 | J26: =G26*5% -> 10 | K26: =G26+J26 -> 210 | L26: MARINELLE
... B95: Trane BVBA (Dubai Branch) | C95: 24-0093 | D95: 45335 | E95: 100235699400003 | F95: Crystal Trophy | G95: 1800 | I95: =G95-H95 -> 1800 | J95: =G95*5% -> 90 | K95: =G95+J95 -> 1890 | L95: REENA
B96: Krishna International FZCO | C96: 24-0094 | D96: 45332 | E96: 100060213400003 | F96: Wedding Luggage Tags | G96: 13000 | I96: =G96-H96 -> 13000 | J96: =G96*5% -> 650 | K96: =G96+J96 -> 13650 | L96: REENA
B97: One Blue Clover FZCO | C97: 24-0095 | D97: 45338 | E97: - | F97: Letterhead | G97: 525 | I97: =G97-H97 -> 525 | J97: =G97*5% -> 26.25 | K97: =G97+J97 -> 551.25 | L97: BNI
B98: Stellar Advertising LLC | C98: 24-0096 | D98: 45337 | E98: 100542487200003 | F98: Selfie Frame - DBSJP , Prop - #Outstanding | G98: 595 | I98: =G98-H98 -> 595 | J98: =G98*5% -> 29.75 | K98: =G98+J98 -> 624.75 | L98: REENA
B99: Stellar Advertising LLC | C99: 24-0097 | D99: 45338 | E99: 100542487200003 | F99: Roll Up - AAG | G99: 145 | I99: =G99-H99 -> 145 | J99: =G99*5% -> 7.25 | K99: =G99+J99 -> 152.25 | L99: REENA
B100: M E A D Medical Supplies & Equipment L.L.C | C100: 24-0098 | D100: 45341 | E100: 100540543400003 | F100: NCR Book , Business Cards | G100: 860 | I100: =G100-H100 -> 860 | J100: =G100*5% -> 43 | K100: =G100+J100 -> 903 | L100: MARINELLE
B101: Stellar Advertising LLC | C101: 24-0099 | D101: 45342 | E101: 100542487200003 | F101: Letterhead - FICHTE | G101: 625 | I101: =G101-H101 -> 625 | J101: =G101*5% -> 31.25 | K101: =G101+J101 -> 656.25 | L101: REENA
B102: Golden Tower Technologies | C102: 24-0100 | D102: 45338 | E102: 100470289800003 | F102: Flex to be changed for existing light box | G102: 8850 | I102: =G102-H102 -> 8850 | J102: =G102*5% -> 442.5 | K102: =G102+J102 -> 9292.5 | L102: REENA
B103: Thermo Fisher Scientific S.P.A. | C103: 24-0101 | D103: 45338 | E103: IT 07817950152 | F103: Flyer , Recycled 6-in-1 Charging Cable | G103: 3335 | I103: =G103-H103 -> 3335 | J103: =G103*5% -> 166.75 | K103: =G103+J103 -> 3501.75 | L103: MARINELLE
B104: Griffith College | C104: 24-0102 | D104: 45338 | E104: - | F104: Brochure | G104: 1225 | I104: =G104-H104 -> 1225 | J104: =G104*5% -> 61.25 | K104: =G104+J104 -> 1286.25 | L104: REENA
B105: IDP EDUCATION L.L.C | C105: 24-0103 | D105: 45341 | E105: 100593105800003 | F105: Dubai Roadshow Millenium Downtown, 17th Feb 2024 | G105: 103245.5 | I105: =G105-H105 -> 103245.5 | J105: =G105*5% -> 5162.275 | K105: =G105+J105 -> 108407.77 | L105: REENA
B106: IDP EDUCATION L.L.C | C106: 24-0104 | D106: 45341 | E106: 100593105800003 | F106: Abu Dhabi Roadshow 18 Feb 2024, InterContinental | G106: 51717.75 | I106: =G106-H106 -> 51717.75 | J106: =G106*5% -> 2585.8875 | K106: =G106+J106 -> 54303.637 | L106: REENA
B107: DYNAMIC EMPLOYMENT SERVICES L.L.C | C107: 24-0105 | D107: 45343 | E107: 100323347300003 | F107: Parking Signage | G107: 892.5 | I107: =G107-H107 -> 892.5 | J107: =G107*5% -> 44.625 | K107: =G107+J107 -> 937.125 | L107: MARINELLE
B108: Stellar Advertising LLC | C108: 24-0106 | D108: 45343 | E108: 100542487200003 | F108: Flyer - Taylor Wessing | G108: 190 | I108: =G108-H108 -> 190 | J108: =G108*5% -> 9.5 | K108: =G108+J108 -> 199.5 | L108: REENA
B109: Stellar Advertising LLC | C109: 24-0107 | D109: 45342 | E109: 100542487200003 | F109: Journal - DBSEH | G109: 585 | I109: =G109-H109 -> 585 | J109: =G109*5% -> 29.25 | K109: =G109+J109 -> 614.25 | L109: REENA
...

Sheet Summary REA Ins
B3: Sum of INVOICE SUB-TOTAL | C3: 2024 | L3: Summary Sales per Month | M3: 2024
B4: Client Names | C4: Jan | D4: Feb | E4: Grand Total | L4: Team | M4: Jan | N4: Feb | O4: Grand Total
B5: Continental Middle East DMCC | C5: 450 | E5: 450 | L5: REENA | M5: 750 | N5: 1100 | O5: 1850
B6: IDP EDUCATION L.L.C | C6: 300 | D6: 1100 | E6: 1400 | L6: Grand Total | M6: 750 | N6: 1100 | O6: 1850
B7: Grand Total | C7: 750 | D7: 1100 | E7: 1850

Sheet 2024-curated
A1: 2024 - REA Advertising - Month wise Customer wise Sales History ( WITHOUT VAT)
B4: Client Names | C4: Jan | D4: Feb | E4: Mar | F4: Apr | G4: May | H4: Jun | I4: Jul | J4: Grand Total | K4: No of Invoices | L4: Average Amount | M4: Average /month
B5: TOP 10
A6: 1 | B6: IDP EDUCATION L.L.C | C6: 5040.907 | D6: 165010.85 | E6: 585 | F6: 4197 | G6: 16715.67 | H6: 160 | I6: 3845 | J6: 195554.43 | K6: 28 | L6: =J6/K6 -> 6984.0867 | M6: =+J6/7 -> 27936.347
A7: 2 | B7: Stellar Advertising LLC | C7: 9650.49 | D7: 16015.5 | E7: 18431 | F7: 9871 | G7: 20166.02 | H7: 76627.75 | I7: 13364.81 | J7: 164126.57 | K7: 90 | L7: =J7/K7 -> 1823.6286 | M7: =+J7/7 -> 23446.653
A8: 3 | B8: Navitas Middle East FZ - LLC | C8: 10803.35 | E8: 12395 | F8: 4669 | G8: 18700 | H8: 35007.5 | I8: 977 | J8: 82551.85 | K8: 34 | L8: =J8/K8 -> 2427.9956 | M8: =+J8/7 -> 11793.121
A9: 4 | B9: MSB Private School | H9: 45667.08 | J9: 45667.08 | K9: 1 | L9: =J9/K9 -> 45667.08 | M9: =+J9/7 -> 6523.8686
A10: 5 | B10: Dubai Academic Health Corporation (DAHC) | E10: 6920 | G10: 12375 | H10: 24338.5 | J10: 43633.5 | K10: 5 | L10: =J10/K10 -> 8726.7 | M10: =+J10/7 -> 6233.3571
A11: 6 | B11: SWISS BUSINESS COUNCIL (DMCC BRANCH) | H11: 39130 | J11: 39130 | K11: 1 | L11: =J11/K11 -> 39130 | M11: =+J11/7 -> 5590
A12: 7 | B12: DUNECREST AMERICAN SCHOOL L.L.C | C12: 19193.5 | G12: 3831.3 | H12: 358.75 | I12: 14110 | J12: 37493.55 | K12: 8 | L12: =J12/K12 -> 4686.6938 | M12: =+J12/7 -> 5356.2214
A13: 8 | B13: GrokGlobal Services | C13: 4475 | E13: 22177.5 | F13: 310 | G13: 975 | H13: 6445 | I13: 275 | J13: 34657.5 | K13: 10 | L13: =J13/K13 -> 3465.75 | M13: =+J13/7 -> 4951.0714
A14: 9 | B14: Gulftainer | E14: 31080.87 | G14: 1240 | J14: 32320.87 | K14: 8 | L14: =J14/K14 -> 4040.1088 | M14: =+J14/7 -> 4617.2671
A15: 10 | B15: DHR MENA FZ-LLC | F15: 29332.5 | J15: 29332.5 | K15: 2 | L15: =J15/K15 -> 14666.25 | M15: =+J15/7 -> 4190.3571
C16: =SUM(C6:C15) -> 49163.247 | D16: =SUM(D6:D15) -> 181026.35 | E16: =SUM(E6:E15) -> 91589.37 | F16: =SUM(F6:F15) -> 48379.5 | G16: =SUM(G6:G15) -> 74002.99 | H16: =SUM(H6:H15) -> 227734.58 | I16: =SUM(I6:I15) -> 32571.81 | J16: =SUM(J6:J15) -> 704467.85 | K16: =SUM(K6:K15) -> 187 | L16: =+J16/K16 -> 3767.2077 | M16: =SUM(M6:M15) -> 100638.26 | N16: =+J16/J132*100 -> 62.512486
B18: THE NEXT 20- GROUP A
A19: 1 | B19: PLUS971 CYBER SECURITY L.L.C | F19: 24100 | J19: 24100 | K19: 3 | L19: =J19/K19 -> 8033.3333 | M19: =+J19/7 -> 3442.8571
A20: 2 | B20: Trane BVBA (Dubai Branch) | C20: 6380 | D20: 3000 | E20: 3370 | F20: 1250 | G20: 4864 | H20: 1731 | I20: 1669 | J20: 22264 | K20: 30 | L20: =J20/K20 -> 742.13333 | M20: =+J20/7 -> 3180.5714
A21: 3 | B21: Ducon Industries FZCO (Dubai Branch) | I21: 17900 | J21: 17900 | K21: 1 | L21: =J21/K21 -> 17900 | M21: =+J21/7 -> 2557.1429
A22: 4 | B22: BorgRollsWarner Middle East LLC | C22: 14375 | I22: 1933.5 | J22: 16308.5 | K22: 2 | L22: =J22/K22 -> 8154.25 | M22: =+J22/7 -> 2329.7857
A23: 5 | B23: TETR, College of Business | G23: 11490.5 | H23: 4517.5 | J23: 16008 | K23: 5 | L23: =J23/K23 -> 3201.6 | M23: =+J23/7 -> 2286.8571
A24: 6 | B24: Radiometer Medical ApS | C24: 14677.74 | F24: 325 | J24: 15002.74 | K24: 3 | L24: =J24/K24 -> 5000.9133 | M24: =+J24/7 -> 2143.2486
A25: 7 | B25: Lloyds Energy DMCC | C25: 1250 | E25: 9475 | F25: 1100 | H25: 870 | I25: 435 | J25: 13130 | K25: 8 | L25: =J25/K25 -> 1641.25 | M25: =+J25/7 -> 1875.7143
A26: 8 | B26: Krishna International FZCO | D26: 13000 | J26: 13000 | K26: 1 | L26: =J26/K26 -> 13000 | M26: =+J26/7 -> 1857.1429
A27: 9 | B27: M E A D Medical Supplies & Equipment L.L.C | C27: 475 | D27: 1347.5 | G27: 1060 | H27: 10070 | J27: 12952.5 | K27: 6 | L27: =J27/K27 -> 2158.75 | M27: =+J27/7 -> 1850.3571
A28: 10 | B28: AL NASER INTERNATIONAL FZE | C28: 1445 | D28: 9450 | G28: 430 | H28: 485 | I28: 575 | J28: 12385 | K28: 16 | L28: =J28/K28 -> 774.0625 | M28: =+J28/7 -> 1769.2857
A29: 11 | B29: Al Jalila Foundation | H29: 11142.25 | J29: 11142.25 | K29: 2 | L29: =J29/K29 -> 5571.125 | M29: =+J29/7 -> 1591.75
A30: 12 | B30: Byyu Gift Trading LLC | E30: 4225 | G30: 350 | H30: 5935 | I30: 485 | J30: 10995 | K30: 5 | L30: =J30/K30 -> 2199 | M30: =+J30/7 -> 1570.7143
A31: 13 | B31: Al Tayer Insignia LLC | D31: 10965 | J31: 10965 | K31: 1 | L31: =J31/K31 -> 10965 | M31: =+J31/7 -> 1566.4286
A32: 14 | B32: Golden Tower Technologies | D32: 8850 | J32: 8850 | K32: 1 | L32: =J32/K32 -> 8850 | M32: =+J32/7 -> 1264.2857
A33: 15 | B33: Tappy Toes Nursery DWC-LLC | D33: 989 | G33: 7425 | J33: 8414 | K33: 2 | L33: =J33/K33 -> 4207 | M33: =+J33/7 -> 1202
A34: 16 | B34: Azalee Flower Boutique Limited | G34: 8385 | J34: 8385 | K34: 1 | L34: =J34/K34 -> 8385 | M34: =+J34/7 -> 1197.8571
A35: 17 | B35: GRAND STAR ALUMINUM & GLASS L.L.C | C35: 8360 | J35: 8360 | K35: 2 | L35: =J35/K35 -> 4180 | M35: =+J35/7 -> 1194.2857
A36: 18 | B36: Continental Middle East DMCC | D36: 3835 | G36: 1266 | H36: 3086 | J36: 8187 | K36: 5 | L36: =J36/K36 -> 1637.4 | M36: =+J36/7 -> 1169.5714
A37: 19 | B37: JUBAILI BROS S.A.L. | C37: 5975 | G37: 1612.5 | J37: 7587.5 | K37: 2 | L37: =J37/K37 -> 3793.75 | M37: =+J37/7 -> 1083.9286
A38: 20 | B38: Aurantius Real Estate Broker | C38: 553.75 | D38: 2410.5 | E38: 792.5 | G38: 869 | H38: 2138 | I38: 725 | J38: 7488.75 | K38: 9 | L38: =J38/K38 -> 832.08333 | M38: =+J38/7 -> 1069.8214
C39: =SUM(C19:C38) -> 53491.49 | D39: =SUM(D19:D38) -> 53847 | E39: =SUM(E19:E38) -> 17862.5 | F39: =SUM(F19:F38) -> 26775 | G39: =SUM(G19:G38) -> 37752 | H39: =SUM(H19:H38) -> 39974.75 | I39: =SUM(I19:I38) -> 23722.5 | J39: =SUM(J19:J38) -> 253425.24 | K39: =SUM(K19:K38) -> 105 | L39: =+J39/K39 -> 2413.5737 | M39: =SUM(M19:M38) -> 36203.606 | N39: =+J39/J132*100 -> 22.48824
B41: THEY GAVE US BUSINESS TOO !!!
A42: 1 | B42: Huxley Associates Global Limited | C42: 1125 | D42: 225 | F42: 375 | G42: 4355 | H42: 1233.75 | J42: 7313.75 | K42: 6 | L42: =J42/K42 -> 1218.9583 | M42: =+J42/7 -> 1044.8214
A43: 2 | B43: Tristar Transport LLC | C43: 1140 | F43: 6000 | J43: 7140 | K43: 2 | L43: =J43/K43 -> 3570 | M43: =+J43/7 -> 1020
A44: 3 | B44: Liquid Telecommunications International FZE | D44: 6775 | J44: 6775 | K44: 2 | L44: =J44/K44 -> 3387.5 | M44: =+J44/7 -> 967.85714
...

Sheet 2024
B3: Column Labels
B4: Jan | D4: Feb | F4: Mar | H4: Apr | J4: May | L4: Jun | N4: Jul | P4: Aug | R4: Total Sum of INVOICE SUB-TOTAL | S4: Total Sum of No of invoice
A5: Row Labels | B5: Sum of INVOICE SUB-TOTAL | C5: Sum of No of invoice | D5: Sum of INVOICE SUB-TOTAL | E5: Sum of No of invoice | F5: Sum of INVOICE SUB-TOTAL | G5: Sum of No of invoice | H5: Sum of INVOICE SUB-TOTAL | I5: Sum of No of invoice | J5: Sum of INVOICE SUB-TOTAL | K5: Sum of No of invoice | L5: Sum of INVOICE SUB-TOTAL | M5: Sum of No of invoice | N5: Sum of INVOICE SUB-TOTAL | O5: Sum of No of invoice | P5: Sum of INVOICE SUB-TOTAL | Q5: Sum of No of invoice
A6: IDP EDUCATION L.L.C | B6: 4813 | C6: 3 | D6: 165010.85 | E6: 8 | F6: 585 | G6: 1 | H6: 4197 | I6: 3 | J6: 16715.67 | K6: 9 | L6: 160 | M6: 1 | N6: 5885 | O6: 3 | R6: 197366.52 | S6: 28
A7: Stellar Advertising LLC | B7: 9650.49 | C7: 10 | D7: 16015.5 | E7: 10 | F7: 18431 | G7: 14 | H7: 9871 | I7: 10 | J7: 20166.02 | K7: 21 | L7: 76627.75 | M7: 18 | N7: 15382.81 | O7: 10 | R7: 166144.57 | S7: 93
A8: Navitas Middle East FZ - LLC | B8: 10803.35 | C8: 4 | F8: 550 | G8: 2 | H8: 4669 | I8: 4 | J8: 12497.5 | K8: 9 | L8: 33682.5 | M8: 3 | N8: 977 | O8: 2 | R8: 63179.35 | S8: 24
A9: MSB Private School | L9: 45667.08 | M9: 1 | R9: 45667.08 | S9: 1
A10: Dubai Academic Health Corporation (DAHC) | F10: 6920 | G10: 1 | J10: 12375 | K10: 1 | L10: 24338.5 | M10: 3 | R10: 43633.5 | S10: 5
A11: SWISS BUSINESS COUNCIL (DMCC BRANCH) | L11: 39130 | M11: 1 | R11: 39130 | S11: 1
A12: DUNECREST AMERICAN SCHOOL L.L.C | B12: 19193.5 | C12: 2 | J12: 3831.3 | K12: 4 | L12: 358.75 | M12: 1 | N12: 14110 | O12: 1 | R12: 37493.55 | S12: 8
A13: GrokGlobal Services | B13: 4475 | C13: 2 | F13: 22177.5 | G13: 3 | H13: 310 | I13: 1 | J13: 975 | K13: 1 | L13: 6445 | M13: 2 | N13: 275 | O13: 1 | R13: 34657.5 | S13: 10
A14: DHR MENA FZ-LLC | H14: 29332.5 | I14: 2 | R14: 29332.5 | S14: 2
A15: Ducon Industries FZCO (Dubai Branch) | N15: 24876 | O15: 2 | R15: 24876 | S15: 2
A16: PLUS971 CYBER SECURITY L.L.C | H16: 24100 | I16: 3 | R16: 24100 | S16: 3
A17: Trane BVBA (Dubai Branch) | B17: 5975 | C17: 5 | D17: 3000 | E17: 4 | F17: 2830 | G17: 4 | H17: 405 | I17: 1 | J17: 4864 | K17: 7 | L17: 1731 | M17: 2 | N17: 4369 | O17: 4 | R17: 23174 | S17: 27
A18: BorgRollsWarner Middle East LLC | B18: 14375 | C18: 1 | N18: 1933.5 | O18: 1 | R18: 16308.5 | S18: 2
A19: Lloyds Energy DMCC | B19: 1250 | C19: 1 | F19: 9475 | G19: 3 | H19: 1100 | I19: 1 | L19: 870 | M19: 2 | N19: 3110 | O19: 2 | R19: 15805 | S19: 9
A20: Radiometer Medical ApS | B20: 14677.74 | C20: 2 | H20: 325 | I20: 1 | R20: 15002.74 | S20: 3
A21: Gulftainer | F21: 12626.25 | G21: 3 | J21: 1240 | K21: 1 | R21: 13866.25 | S21: 4
A22: Continental Middle East DMCC | D22: 3835 | E22: 2 | J22: 1266 | K22: 1 | L22: 3086 | M22: 2 | N22: 5528.75 | O22: 1 | R22: 13715.75 | S22: 6
A23: Krishna International FZCO | D23: 13000 | E23: 1 | R23: 13000 | S23: 1
A24: M E A D Medical Supplies & Equipment L.L.C | B24: 475 | C24: 1 | D24: 1347.5 | E24: 2 | J24: 1060 | K24: 1 | L24: 10070 | M24: 2 | R24: 12952.5 | S24: 6
A25: TETR, College of Business | J25: 11490.5 | K25: 3 | R25: 11490.5 | S25: 3
A26: Al Jalila Foundation | L26: 11142.25 | M26: 2 | R26: 11142.25 | S26: 2
A27: Byyu Gift Trading LLC | F27: 4225 | G27: 2 | J27: 350 | K27: 1 | L27: 5935 | M27: 1 | N27: 485 | O27: 1 | R27: 10995 | S27: 5
A28: Al Tayer Insignia LLC | D28: 10965 | E28: 1 | R28: 10965 | S28: 1
A29: Navitas - Murdoch University | F29: 10720 | G29: 3 | R29: 10720 | S29: 3
A30: Golden Tower Technologies | D30: 8850 | E30: 1 | R30: 8850 | S30: 1
A31: Navitas SAE FZ-LLC | F31: 1125 | G31: 3 | J31: 6202.5 | K31: 3 | L31: 1325 | M31: 1 | R31: 8652.5 | S31: 7
A32: Momentum Logistics | F32: 8463.75 | G32: 1 | R32: 8463.75 | S32: 1
A33: Tappy Toes Nursery DWC-LLC | D33: 989 | E33: 1 | J33: 7425 | K33: 1 | R33: 8414 | S33: 2
A34: Azalee Flower Boutique Limited | J34: 8385 | K34: 1 | R34: 8385 | S34: 1
A35: GRAND STAR ALUMINUM & GLASS L.L.C | B35: 8360 | C35: 2 | R35: 8360 | S35: 2
A36: Aurantius Real Estate Broker | B36: 553.75 | C36: 2 | D36: 2410.5 | E36: 2 | F36: 792.5 | G36: 1 | J36: 869 | K36: 1 | L36: 2138 | M36: 2 | N36: 1000 | O36: 2 | R36: 7763.75 | S36: 10
A37: JUBAILI BROS S.A.L. | B37: 5975 | C37: 1 | J37: 1612.5 | K37: 1 | R37: 7587.5 | S37: 2
A38: Gulftainer Company Limited - Iraq Branch | F38: 7493.15 | G38: 2 | R38: 7493.15 | S38: 2
A39: Huxley Associates Global Limited | B39: 1125 | C39: 1 | D39: 225 | E39: 1 | H39: 375 | I39: 1 | J39: 4355 | K39: 2 | L39: 1233.75 | M39: 1 | R39: 7313.75 | S39: 6
A40: Tristar Transport LLC | B40: 1140 | C40: 1 | H40: 6000 | I40: 1 | R40: 7140 | S40: 2
A41: Liquid Telecommunications International FZE | D41: 6775 | E41: 2 | R41: 6775 | S41: 2
A42: Pacific Link | F42: 6625 | G42: 2 | R42: 6625 | S42: 2
...

Sheet COMP
A2: AL NASER INTERNATIONAL FZE | B2: AL NASER INTERNATIONAL FZE
B3: AUSTRAL INTERNATIONAL DMCC
B4: AUSTRAL INTERNATIONAL FZE
B5: LAYAN TRADING FZE
B6: ARAM
A8: GULFTAINER | B8: GULFTAINER
A9: GULFTAINER | B9: GULTAINER COMPANY LIMITED - IRAQ BRANCH
B10: MOMENTUM COMPANY LIMITED SAUDI ARABIA
B11: MOMENTUM LOGISTICS
A13: MURDOCH | B13: NAVITAS - MURDOCH UNIVERSITY
B14: NAVITAS MIDDLE EAST FZ - LLC
B15: NAVITAS SAE FZ - LLC
A17: THERMO FISHER | B17: THERMO FISHER SCIENTIFIC MIDDLE EAST
A18: THERMO FISHER | B18: THERMO FISHER SCIENTIFIC S.P.A
A21: UNIQUE WORLD BUSINESS | B21: UNIQUE WORLD BUSINESS CENTRE LLC
B22: UNIQUE WORLD BUSINESS CENTRE LLC-(BR)
B23: UNIQUE WORLD BUSINESS CENTRE LLC-(HO)

Sheet REA Ins - Inv
B2: CLIENT | C2: INVOICE NO. | D2: INVOICE DATE | E2: CLIENT TRN | F2: DESCRIPTION | G2: INVOICE SUB-TOTAL | H2: Rebate | I2: Invoice Sub-Total after Rebate | J2: VAT % AMOUNT | K2: TOTAL INVOICE AMOUNT | L2: Sales Person | N2: =SUM(G:G) -> 1850
B3: Continental Middle East DMCC | C3: 24-0001 | D3: 45310 | E3: 100377505100003 | F3: Trophy - RONY DOMINIC | G3: 450 | I3: =G3-H3 -> 450 | J3: =G3*5% -> 22.5 | K3: =G3+J3 -> 472.5 | L3: REENA
B4: IDP EDUCATION L.L.C | C4: 24-0002 | D4: 45320 | E4: 100593105800003 | F4: Rubber Stamp | G4: 300 | I4: =G4-H4 -> 300 | J4: =G4*5% -> 15 | K4: =G4+J4 -> 315 | L4: REENA
B5: IDP EDUCATION L.L.C | C5: 24-0003 | D5: 45348 | E5: 100593105800003 | F5: Business Cards - Dubai | G5: 720 | I5: =G5-H5 -> 720 | J5: =G5*5% -> 36 | K5: =G5+J5 -> 756 | L5: REENA
B6: IDP EDUCATION L.L.C | C6: 24-0004 | D6: 45350 | E6: 100593105800003 | F6: Name Tags , Expo Cards | G6: 380 | I6: =G6-H6 -> 380 | J6: =G6*5% -> 19 | K6: =G6+J6 -> 399 | L6: REENA
G7: 0 | I7: =G7-H7 -> 0 | J7: =G7*5% -> 0 | K7: =G7+J7 -> 0
G8: 0 | I8: =G8-H8 -> 0 | J8: =G8*5% -> 0 | K8: =G8+J8 -> 0
G9: 0 | I9: =G9-H9 -> 0 | J9: =G9*5% -> 0 | K9: =G9+J9 -> 0
G10: 0 | I10: =G10-H10 -> 0 | J10: =G10*5% -> 0 | K10: =G10+J10 -> 0
G11: 0 | I11: =G11-H11 -> 0 | J11: =G11*5% -> 0 | K11: =G11+J11 -> 0
G12: 0 | I12: =G12-H12 -> 0 | J12: =G12*5% -> 0 | K12: =G12+J12 -> 0
G13: 0 | I13: =G13-H13 -> 0 | J13: =G13*5% -> 0 | K13: =G13+J13 -> 0
G14: 0 | I14: =G14-H14 -> 0 | J14: =G14*5% -> 0 | K14: =G14+J14 -> 0
G15: 0 | I15: =G15-H15 -> 0 | J15: =G15*5% -> 0 | K15: =G15+J15 -> 0
